Workbook

Sheet Enunciado
A1: Ejemplo 4.2 — PERT probabilístico (material de referencia)
A2: Enunciado y datos de entrada
A4: Fuente | B4: CONCEPTOS GENERALES — hoja PERT Probabilístico
A5: Unidad de tiempo | B5: semanas
A6: Método | B6: PERT (t_e = (a + b + 4m)/6 alimenta el CPM)
A7: options | B7: probability_method=table; variance_strategy=max_variance_path
A9: Preguntas del ejercicio
A10: Parte | B10: Pregunta | C10: Salidas solicitadas
A11: a | B11: Represente el proyecto mediante una red ACTIVIDAD - NODO | C11: Red actividad-nodo
A12: b | B12: Calcule el tiempo esperado y la varianza de cada actividad, suponiendo una distribución beta unimodal de probabilidad. | C12: Tiempo esperado y varianza por actividad
A13: c | B13: Calcule el tiempo de inicio esperado más temprano, el tiempo de inicio esperado más tarde, el tiempo de finalización esperado más temprano, el tiempo de finalización esperado más tarde y la holgura esperada, para cada una de las actividades del proyecto. | C13: Tiempos de inicio y terminación, Holguras
A14: d | B14: Especifique la ruta crítica, el tiempo esperado de conclusión del proyecto y su varianza esperada. | C14: Ruta crítica, Duración del proyecto, Varianza del proyecto
A15: e | B15: Encuentre la probabilidad de que las actividades de la ruta crítica concluyan dentro de 27 semanas; dentro de 25 semanas; dentro de 23 semanas;, en más de 27 semanas; entre 25 y 27 semanas. | C15: Probabilidades de terminación
A16: f | B16: ¿Cuántas semanas permitirá una probabilidad del 90%, para concluir la ruta crítica a tiempo? | C16: Duración para una probabilidad objetivo
A18: Salidas solicitadas | B18: Red actividad-nodo, Tiempos de inicio y terminación, Holguras, Ruta crítica, Duración del proyecto, Varianza del proyecto, Tiempo esperado y varianza por actividad, Probabilidades de terminación, Duración para una probabilidad objetivo
A20: Consultas de probabilidad
A21: id | B21: Tipo | C21: ≥ | D21: ≤ | E21: p | F21: Procedencia | G21: Fuente
A22: e1 | B22: AT_MOST | D22: 27 | F22: Inferido | G22: encuentre la probabilidad de que las actividades de la ruta critica concluyan dentro de 27 semanas
A23: e2 | B23: AT_MOST | D23: 25 | F23: Inferido | G23: dentro de 25 semanas
A24: e3 | B24: AT_MOST | D24: 23 | F24: Inferido | G24: dentro de 23 semanas
A25: e4 | B25: AT_LEAST | C25: 27 | F25: Inferido | G25: , en mas de 27 semanas
A26: e5 | B26: BETWEEN | C26: 25 | D26: 27 | F26: Inferido | G26: entre 25 y 27 semanas.
A27: f | B27: PERCENTILE_TO_DURATION | E27: 0.9 | F27: Inferido | G27: ¿Cuántas semanas permitirá una probabilidad del 90%, para concluir la ruta crítica a tiempo?
A29: Red original ACTIVIDAD - FLECHA y precedencias deducidas
A30: Actividad | B30: Nodo inicial | C30: Nodo final | D30: Predecesoras | E30: Vía ficticias | F30: Justificación
A31: A | B31: 1 | C31: 2 | D31: Ninguna | F31: La flecha A sale del nodo 1, al que no llega ninguna actividad: actividad inicial.
A32: B | B32: 2 | C32: 3 | D32: A | F32: La flecha B sale del nodo 2; llegan al nodo 2: A.
A33: C | B33: 3 | C33: 6 | D33: B | F33: La flecha C sale del nodo 3; llegan al nodo 3: B.
A34: D | B34: 3 | C34: 5 | D34: B | F34: La flecha D sale del nodo 3; llegan al nodo 3: B.
A35: E | B35: 2 | C35: 4 | D35: A | F35: La flecha E sale del nodo 2; llegan al nodo 2: A.
A36: F | B36: 5 | C36: 6 | D36: D, E | E36: ficticia_4_5 | F36: La flecha F sale del nodo 5; llegan al nodo 5: D; por la(s) ficticia(s) ficticia_4_5 también depende de E.
A37: G | B37: 6 | C37: 7 | D37: C, F | F37: La flecha G sale del nodo 6; llegan al nodo 6: C, F.
A38: H | B38: 4 | C38: 7 | D38: E | F38: La flecha H sale del nodo 4; llegan al nodo 4: E.
A39: I | B39: 7 | C39: 8 | D39: G, H | F39: La flecha I sale del nodo 7; llegan al nodo 7: G, H.
A41: Supuestos e inferencias
A42: Campo | B42: Valor | C42: Justificación | D42: Procedencia
A43: requested_outputs | B43: NETWORK_DIAGRAM | C43: Question 'a' asks for it. | D43: Inferido
A44: requested_outputs | B44: ACTIVITY_ESTIMATES | C44: Question 'b' asks for it. | D44: Inferido
A45: requested_outputs | B45: EARLY_LATE_TIMES | C45: Question 'c' asks for it. | D45: Inferido
A46: requested_outputs | B46: SLACK | C46: Question 'c' asks for it. | D46: Inferido
...

Sheet Datos
A1: Datos de las actividades
A2: Unidad de tiempo: semanas · Método: PERT (t_e = (a + b + 4m)/6 alimenta el CPM)
A4: Actividad | B4: Descripción | C4: Predecesoras | D4: Ficticia | E4: Optimista (a) | F4: Normal (m) | G4: Pesimista (b) | H4: Procedencia
A5: A | C5: Ninguna | D5: No | E5: 1 | F5: 3 | G5: 5 | H5: Extraído del documento (predecessors: Inferido)
A6: B | C6: A | D6: No | E6: 1 | F6: 3 | G6: 5 | H6: Extraído del documento (predecessors: Inferido)
A7: C | C7: B | D7: No | E7: 4 | F7: 5 | G7: 6 | H7: Extraído del documento (predecessors: Inferido)
A8: D | C8: B | D8: No | E8: 1 | F8: 4 | G8: 7 | H8: Extraído del documento (predecessors: Inferido)
A9: E | C9: A | D9: No | E9: 7 | F9: 8 | G9: 9 | H9: Extraído del documento (predecessors: Inferido)
A10: F | C10: D, E | D10: No | E10: 4 | F10: 6 | G10: 8 | H10: Extraído del documento (predecessors: Inferido)
A11: G | C11: C, F | D11: No | E11: 4 | F11: 5 | G11: 6 | H11: Extraído del documento (predecessors: Inferido)
A12: H | C12: E | D12: No | E12: 7 | F12: 9 | G12: 11 | H12: Extraído del documento (predecessors: Inferido)
A13: I | C13: G, H | D13: No | E13: 1 | F13: 3 | G13: 5 | H13: Extraído del documento (predecessors: Inferido)

Sheet PERT
A1: PERT probabilístico: tiempo esperado y varianza por actividad
A2: t_e = (a + b + 4m) / 6 σ² = [(b − a) / 6]²
A5: Actividad | B5: a | C5: m | D5: b | E5: t_e = (a + b + 4m)/6 | F5: σ² = [(b − a)/6]² | G5: t_e (fracción) | H5: σ² (fracción) | I5: Cálculo t_e | J5: Cálculo σ² | K5: ¿Crítica?
A6: A | B6: ='Datos'!$E$5 -> 1 | C6: ='Datos'!$F$5 -> 3 | D6: ='Datos'!$G$5 -> 5 | E6: =(B6+D6+4*C6)/6 -> 3 | F6: =((D6-B6)/6)^2 -> 0.44444444 | G6: 3 | H6: 4/9 | I6: (1 + 5 + 4·3) / 6 = 3 | J6: [(5 − 1) / 6]² = 4/9 | K6: ='CPM'!$L$6 -> Sí
A7: B | B7: ='Datos'!$E$6 -> 1 | C7: ='Datos'!$F$6 -> 3 | D7: ='Datos'!$G$6 -> 5 | E7: =(B7+D7+4*C7)/6 -> 3 | F7: =((D7-B7)/6)^2 -> 0.44444444 | G7: 3 | H7: 4/9 | I7: (1 + 5 + 4·3) / 6 = 3 | J7: [(5 − 1) / 6]² = 4/9 | K7: ='CPM'!$L$7 -> No
A8: C | B8: ='Datos'!$E$7 -> 4 | C8: ='Datos'!$F$7 -> 5 | D8: ='Datos'!$G$7 -> 6 | E8: =(B8+D8+4*C8)/6 -> 5 | F8: =((D8-B8)/6)^2 -> 0.11111111 | G8: 5 | H8: 1/9 | I8: (4 + 6 + 4·5) / 6 = 5 | J8: [(6 − 4) / 6]² = 1/9 | K8: ='CPM'!$L$8 -> No
A9: D | B9: ='Datos'!$E$8 -> 1 | C9: ='Datos'!$F$8 -> 4 | D9: ='Datos'!$G$8 -> 7 | E9: =(B9+D9+4*C9)/6 -> 4 | F9: =((D9-B9)/6)^2 -> 1 | G9: 4 | H9: 1 | I9: (1 + 7 + 4·4) / 6 = 4 | J9: [(7 − 1) / 6]² = 1 | K9: ='CPM'!$L$9 -> No
A10: E | B10: ='Datos'!$E$9 -> 7 | C10: ='Datos'!$F$9 -> 8 | D10: ='Datos'!$G$9 -> 9 | E10: =(B10+D10+4*C10)/6 -> 8 | F10: =((D10-B10)/6)^2 -> 0.11111111 | G10: 8 | H10: 1/9 | I10: (7 + 9 + 4·8) / 6 = 8 | J10: [(9 − 7) / 6]² = 1/9 | K10: ='CPM'!$L$10 -> Sí
A11: F | B11: ='Datos'!$E$10 -> 4 | C11: ='Datos'!$F$10 -> 6 | D11: ='Datos'!$G$10 -> 8 | E11: =(B11+D11+4*C11)/6 -> 6 | F11: =((D11-B11)/6)^2 -> 0.44444444 | G11: 6 | H11: 4/9 | I11: (4 + 8 + 4·6) / 6 = 6 | J11: [(8 − 4) / 6]² = 4/9 | K11: ='CPM'!$L$11 -> Sí
A12: G | B12: ='Datos'!$E$11 -> 4 | C12: ='Datos'!$F$11 -> 5 | D12: ='Datos'!$G$11 -> 6 | E12: =(B12+D12+4*C12)/6 -> 5 | F12: =((D12-B12)/6)^2 -> 0.11111111 | G12: 5 | H12: 1/9 | I12: (4 + 6 + 4·5) / 6 = 5 | J12: [(6 − 4) / 6]² = 1/9 | K12: ='CPM'!$L$12 -> Sí
A13: H | B13: ='Datos'!$E$12 -> 7 | C13: ='Datos'!$F$12 -> 9 | D13: ='Datos'!$G$12 -> 11 | E13: =(B13+D13+4*C13)/6 -> 9 | F13: =((D13-B13)/6)^2 -> 0.44444444 | G13: 9 | H13: 4/9 | I13: (7 + 11 + 4·9) / 6 = 9 | J13: [(11 − 7) / 6]² = 4/9 | K13: ='CPM'!$L$13 -> No
A14: I | B14: ='Datos'!$E$13 -> 1 | C14: ='Datos'!$F$13 -> 3 | D14: ='Datos'!$G$13 -> 5 | E14: =(B14+D14+4*C14)/6 -> 3 | F14: =((D14-B14)/6)^2 -> 0.44444444 | G14: 3 | H14: 4/9 | I14: (1 + 5 + 4·3) / 6 = 3 | J14: [(5 − 1) / 6]² = 4/9 | K14: ='CPM'!$L$14 -> Sí
A16: Ruta crítica utilizada | E16: A – E – F – G – I
A17: Varianza del proyecto σ² = Σ σ² de las actividades críticas | F17: =F6+F10+F11+F12+F14 -> 1.5555556 | G17: 14/9 | I17: σ² = 4/9 + 1/9 + 4/9 + 1/9 + 4/9 = 14/9
A18: Desviación estándar σ = √(Σ σ² A.C.) | F18: =SQRT(F17) -> 1.2472191 | I18: σ = √(14/9) = 1.2472
A19: Tiempo esperado mínimo del proyecto (t_e) | E19: ='CPM'!$D$2 -> 25

Sheet CPM
A1: Método de la ruta crítica — duraciones = tiempo esperado t_e
A2: Tiempo esperado mínimo del proyecto (t_e) (semanas) | D2: =MAX(F14) -> 25
A3: Ruta crítica | D3: A – E – F – G – I
A5: Actividad | B5: Predecesoras | C5: Sucesoras | D5: Duración (t_e) | E5: Inicio más temprano (IC) | F5: Terminación más temprana (TC) | G5: Inicio más tardío (IL) | H5: Terminación más tardía (TL) | I5: Holgura (IL − IC) | J5: Holgura (TL − TC) | K5: Holgura libre | L5: ¿Crítica?
A6: A | B6: — | C6: B, E | D6: ='PERT'!$E$6 -> 3 | E6: 0 | F6: =E6+D6 -> 3 | G6: =H6-D6 -> 0 | H6: =MIN(G7,G10) -> 3 | I6: =ROUND(G6-E6,10) -> 0 | J6: =ROUND(H6-F6,10) -> 0 | K6: =ROUND(MIN(E7,E10)-F6,10) -> 0 | L6: =IF(ABS(I6)<0.000000001,"Sí","No") -> Sí
A7: B | B7: A | C7: C, D | D7: ='PERT'!$E$7 -> 3 | E7: =MAX(F6) -> 3 | F7: =E7+D7 -> 6 | G7: =H7-D7 -> 4 | H7: =MIN(G8,G9) -> 7 | I7: =ROUND(G7-E7,10) -> 1 | J7: =ROUND(H7-F7,10) -> 1 | K7: =ROUND(MIN(E8,E9)-F7,10) -> 0 | L7: =IF(ABS(I7)<0.000000001,"Sí","No") -> No
A8: C | B8: B | C8: G | D8: ='PERT'!$E$8 -> 5 | E8: =MAX(F7) -> 6 | F8: =E8+D8 -> 11 | G8: =H8-D8 -> 12 | H8: =MIN(G12) -> 17 | I8: =ROUND(G8-E8,10) -> 6 | J8: =ROUND(H8-F8,10) -> 6 | K8: =ROUND(MIN(E12)-F8,10) -> 6 | L8: =IF(ABS(I8)<0.000000001,"Sí","No") -> No
A9: D | B9: B | C9: F | D9: ='PERT'!$E$9 -> 4 | E9: =MAX(F7) -> 6 | F9: =E9+D9 -> 10 | G9: =H9-D9 -> 7 | H9: =MIN(G11) -> 11 | I9: =ROUND(G9-E9,10) -> 1 | J9: =ROUND(H9-F9,10) -> 1 | K9: =ROUND(MIN(E11)-F9,10) -> 1 | L9: =IF(ABS(I9)<0.000000001,"Sí","No") -> No
A10: E | B10: A | C10: F, H | D10: ='PERT'!$E$10 -> 8 | E10: =MAX(F6) -> 3 | F10: =E10+D10 -> 11 | G10: =H10-D10 -> 3 | H10: =MIN(G11,G13) -> 11 | I10: =ROUND(G10-E10,10) -> 0 | J10: =ROUND(H10-F10,10) -> 0 | K10: =ROUND(MIN(E11,E13)-F10,10) -> 0 | L10: =IF(ABS(I10)<0.000000001,"Sí","No") -> Sí
A11: F | B11: D, E | C11: G | D11: ='PERT'!$E$11 -> 6 | E11: =MAX(F9,F10) -> 11 | F11: =E11+D11 -> 17 | G11: =H11-D11 -> 11 | H11: =MIN(G12) -> 17 | I11: =ROUND(G11-E11,10) -> 0 | J11: =ROUND(H11-F11,10) -> 0 | K11: =ROUND(MIN(E12)-F11,10) -> 0 | L11: =IF(ABS(I11)<0.000000001,"Sí","No") -> Sí
A12: G | B12: C, F | C12: I | D12: ='PERT'!$E$12 -> 5 | E12: =MAX(F8,F11) -> 17 | F12: =E12+D12 -> 22 | G12: =H12-D12 -> 17 | H12: =MIN(G14) -> 22 | I12: =ROUND(G12-E12,10) -> 0 | J12: =ROUND(H12-F12,10) -> 0 | K12: =ROUND(MIN(E14)-F12,10) -> 0 | L12: =IF(ABS(I12)<0.000000001,"Sí","No") -> Sí
A13: H | B13: E | C13: I | D13: ='PERT'!$E$13 -> 9 | E13: =MAX(F10) -> 11 | F13: =E13+D13 -> 20 | G13: =H13-D13 -> 13 | H13: =MIN(G14) -> 22 | I13: =ROUND(G13-E13,10) -> 2 | J13: =ROUND(H13-F13,10) -> 2 | K13: =ROUND(MIN(E14)-F13,10) -> 2 | L13: =IF(ABS(I13)<0.000000001,"Sí","No") -> No
A14: I | B14: G, H | C14: — | D14: ='PERT'!$E$14 -> 3 | E14: =MAX(F12,F13) -> 22 | F14: =E14+D14 -> 25 | G14: =H14-D14 -> 22 | H14: =$D$2 -> 25 | I14: =ROUND(G14-E14,10) -> 0 | J14: =ROUND(H14-F14,10) -> 0 | K14: =ROUND($D$2-F14,10) -> 0 | L14: =IF(ABS(I14)<0.000000001,"Sí","No") -> Sí
A16: Holgura = IL − IC = TL − TC; actividades con holgura 0 = ruta crítica. IC = máx(TC de predecesoras); TL = mín(IL de sucesoras).

Sheet Red AON
A1: Red ACTIVIDAD - NODO (método de Bernard Roy)
B3: Simbología del nodo
B4: Act. | C4: t | E4: Nombre de la actividad | Duración de la actividad
B5: IC | C5: TC | E5: Tpo. de inicio más temprano | Tpo. de finalización más temprano
B6: IL | C6: TL | E6: Tiempo de inicio más tarde | Tiempo de finalización más tarde
B7: Holgura | E7: Holgura
B9: Diagrama generado por el motor (nodos grises y flechas dobles = ruta crítica).
B36: Nodos con los tiempos calculados | U36: Precedencias (arcos de la red)
B37: A | C37: ='CPM'!$D$6 -> 3 | E37: B | F37: ='CPM'!$D$7 -> 3 | H37: C | I37: ='CPM'!$D$8 -> 5 | K37: F | L37: ='CPM'!$D$11 -> 6 | N37: G | O37: ='CPM'!$D$12 -> 5 | Q37: I | R37: ='CPM'!$D$14 -> 3 | U37: Desde | V37: Hacia | W37: ¿Arco crítico?
B38: ='CPM'!$E$6 -> 0 | C38: ='CPM'!$F$6 -> 3 | E38: ='CPM'!$E$7 -> 3 | F38: ='CPM'!$F$7 -> 6 | H38: ='CPM'!$E$8 -> 6 | I38: ='CPM'!$F$8 -> 11 | K38: ='CPM'!$E$11 -> 11 | L38: ='CPM'!$F$11 -> 17 | N38: ='CPM'!$E$12 -> 17 | O38: ='CPM'!$F$12 -> 22 | Q38: ='CPM'!$E$14 -> 22 | R38: ='CPM'!$F$14 -> 25 | U38: A | V38: B | W38: No
B39: ='CPM'!$G$6 -> 0 | C39: ='CPM'!$H$6 -> 3 | E39: ='CPM'!$G$7 -> 4 | F39: ='CPM'!$H$7 -> 7 | H39: ='CPM'!$G$8 -> 12 | I39: ='CPM'!$H$8 -> 17 | K39: ='CPM'!$G$11 -> 11 | L39: ='CPM'!$H$11 -> 17 | N39: ='CPM'!$G$12 -> 17 | O39: ='CPM'!$H$12 -> 22 | Q39: ='CPM'!$G$14 -> 22 | R39: ='CPM'!$H$14 -> 25 | U39: B | V39: C | W39: No
B40: ='CPM'!$I$6 -> 0 | E40: ='CPM'!$I$7 -> 1 | H40: ='CPM'!$I$8 -> 6 | K40: ='CPM'!$I$11 -> 0 | N40: ='CPM'!$I$12 -> 0 | Q40: ='CPM'!$I$14 -> 0 | U40: B | V40: D | W40: No
U41: A | V41: E | W41: Sí
E42: E | F42: ='CPM'!$D$10 -> 8 | H42: D | I42: ='CPM'!$D$9 -> 4 | U42: D | V42: F | W42: No
E43: ='CPM'!$E$10 -> 3 | F43: ='CPM'!$F$10 -> 11 | H43: ='CPM'!$E$9 -> 6 | I43: ='CPM'!$F$9 -> 10 | U43: E | V43: F | W43: Sí
E44: ='CPM'!$G$10 -> 3 | F44: ='CPM'!$H$10 -> 11 | H44: ='CPM'!$G$9 -> 7 | I44: ='CPM'!$H$9 -> 11 | U44: C | V44: G | W44: No
E45: ='CPM'!$I$10 -> 0 | H45: ='CPM'!$I$9 -> 1 | U45: F | V45: G | W45: Sí
U46: E | V46: H | W46: No
H47: H | I47: ='CPM'!$D$13 -> 9 | U47: G | V47: I | W47: Sí
H48: ='CPM'!$E$13 -> 11 | I48: ='CPM'!$F$13 -> 20 | U48: H | V48: I | W48: No
H49: ='CPM'!$G$13 -> 13 | I49: ='CPM'!$H$13 -> 22
H50: ='CPM'!$I$13 -> 2

Sheet Probabilidad
A1: PERT probabilístico — probabilidad de terminación
A3: Parámetros
A4: Tiempo esperado mínimo del proyecto (t_e) | C4: ='CPM'!$D$2 -> 25
A5: σ² (Σ σ² A.C.) | C5: ='PERT'!$F$17 -> 1.5555556
A6: σ = √σ² | C6: =SQRT(C5) -> 1.2472191
A7: Z = (T_p − t_e) / σ
A8: Tabla: Z redondeado a 2 decimales y P(Z) leído a 4 decimales (convención del material de referencia). Exacto: función NORMSDIST.
A10: Pregunta | B10: Tipo | C10: T_p | D10: Z exacto | E10: P(Z ≤ z) exacta | F10: Z tabla | G10: P(Z ≤ z) tabla | H10: Probabilidad (exacta) | I10: Probabilidad (tabla) | J10: Interpretación
A11: e1 | B11: T ≤ 27 | C11: 27 | D11: =(C11-$C$4)/$C$6 -> 1.6035675 | E11: =NORMSDIST(D11) -> 0.94559528 | F11: =ROUND(D11,2) -> 1.6 | G11: =ROUND(NORMSDIST(F11),4) -> 0.9452 | H11: =E11 -> 0.94559528 | I11: =G11 -> 0.9452 | J11: P(T ≤ 27) = 0.9452
A12: e2 | B12: T ≤ 25 | C12: 25 | D12: =(C12-$C$4)/$C$6 -> 0 | E12: =NORMSDIST(D12) -> 0.5 | F12: =ROUND(D12,2) -> 0 | G12: =ROUND(NORMSDIST(F12),4) -> 0.5 | H12: =E12 -> 0.5 | I12: =G12 -> 0.5 | J12: P(T ≤ 25) = 0.5000
A13: e3 | B13: T ≤ 23 | C13: 23 | D13: =(C13-$C$4)/$C$6 -> -1.6035675 | E13: =NORMSDIST(D13) -> 0.054404715 | F13: =ROUND(D13,2) -> -1.6 | G13: =ROUND(NORMSDIST(F13),4) -> 0.0548 | H13: =E13 -> 0.054404715 | I13: =G13 -> 0.0548 | J13: P(T ≤ 23) = 0.0548
A14: e4 | B14: T ≥ 27 | C14: 27 | D14: =(C14-$C$4)/$C$6 -> 1.6035675 | E14: =NORMSDIST(D14) -> 0.94559528 | F14: =ROUND(D14,2) -> 1.6 | G14: =ROUND(NORMSDIST(F14),4) -> 0.9452 | H14: =1-E14 -> 0.054404715 | I14: =ROUND(1-G14,4) -> 0.0548 | J14: P(T ≥ 27) = 0.0548
A15: e5 | B15: 25 ≤ T ≤ 27 | C15: 27 | D15: =(C15-$C$4)/$C$6 -> 1.6035675 | E15: =NORMSDIST(D15) -> 0.94559528 | F15: =ROUND(D15,2) -> 1.6 | G15: =ROUND(NORMSDIST(F15),4) -> 0.9452 | H15: =E15-E16 -> 0.44559528 | I15: =ROUND(G15-G16,4) -> 0.4452 | J15: P(25 ≤ T ≤ 27) = 0.4452
A16: e5 | B16: 25 ≤ T ≤ 27 | C16: 25 | D16: =(C16-$C$4)/$C$6 -> 0 | E16: =NORMSDIST(D16) -> 0.5 | F16: =ROUND(D16,2) -> 0 | G16: =ROUND(NORMSDIST(F16),4) -> 0.5
A18: Duración para una probabilidad objetivo: T_p = t_e + Z·σ
A19: Pregunta | B19: Probabilidad objetivo | C19: Z exacto | D19: T_p exacto | E19: Z tabla | F19: P(Z ≤ z) tabla | G19: T_p con Z de tabla | H19: Duración a especificar (entero superior) | I19: Interpretación
A20: f | B20: 0.9 | C20: =NORMSINV(B20) -> 1.2815516 | D20: =$C$4+C20*$C$6 -> 26.598376 | E20: 1.29 | F20: =ROUND(NORMSDIST(E20),4) -> 0.9015 | G20: =$C$4+E20*$C$6 -> 26.608913 | H20: =ROUNDUP(ROUND(G20,9),0) -> 27 | I20: P = 0.9 → 27 semanas
A21: Z de tabla = menor Z con 2 decimales cuya P(Z) tabulada alcanza la probabilidad objetivo.

Sheet Resultados
A1: Resultados finales
A2: Ejemplo 4.2 — PERT probabilístico (material de referencia)
A4: Parte | B4: Pregunta | C4: Respuesta | D4: Valor clave (vinculado)
A5: a | B5: Represente el proyecto mediante una red ACTIVIDAD - NODO | C5: Red actividad-nodo en la hoja 'Red AON' con la simbología de nodo de seis casillas.
A6: b | B6: Calcule el tiempo esperado y la varianza de cada actividad, suponiendo una distribución beta unimodal de probabilidad. | C6: (hoja 'PERT') A: t_e = 3, σ² = 4/9; B: t_e = 3, σ² = 4/9; C: t_e = 5, σ² = 1/9; D: t_e = 4, σ² = 1; E: t_e = 8, σ² = 1/9; F: t_e = 6, σ² = 4/9; G: t_e = 5, σ² = 1/9; H: t_e = 9, σ² = 4/9; I: t_e = 3, σ² = 4/9.
A7: c | B7: Calcule el tiempo de inicio esperado más temprano, el tiempo de inicio esperado más tarde, el tiempo de finalización esperado más temprano, el tiempo de finalización esperado más tarde y la holgura esperada, para cada una de las actividades del proyecto. | C7: (hoja 'CPM') A: IC 0, TC 3, IL 0, TL 3, holgura 0; B: IC 3, TC 6, IL 4, TL 7, holgura 1; C: IC 6, TC 11, IL 12, TL 17, holgura 6; D: IC 6, TC 10, IL 7, TL 11, holgura 1; E: IC 3, TC 11, IL 3, TL 11, holgura 0; F: IC 11, TC 17, IL 11, TL 17, holgura 0; G: IC 17, TC 22, IL 17, TL 22, holgura 0; H: IC 11, TC 20, IL 13, TL 22, holgura 2; I: IC 22, TC 25, IL 22, TL 25, holgura 0.
A8: d | B8: Especifique la ruta crítica, el tiempo esperado de conclusión del proyecto y su varianza esperada. | C8: Ruta crítica: A – E – F – G – I. Tiempo esperado mínimo del proyecto (t_e): 25 semanas. Varianza del proyecto: σ² = 4/9 + 1/9 + 4/9 + 1/9 + 4/9 = 14/9 ≈ 1.5556; desviación estándar σ = √(14/9) = 1.2472. | D8: ='CPM'!$D$3 -> A – E – F – G – I
A9: e | B9: Encuentre la probabilidad de que las actividades de la ruta crítica concluyan dentro de 27 semanas; dentro de 25 semanas; dentro de 23 semanas;, en más de 27 semanas; entre 25 y 27 semanas. | C9: P(T ≤ 27) = 0.9452 (Z = 1.6036; exacta: 0.9456); P(T ≤ 25) = 0.5000 (Z = 0; exacta: 0.5000); P(T ≤ 23) = 0.0548 (Z = -1.6036; exacta: 0.0544); P(T ≥ 27) = 0.0548 (Z = 1.6036; exacta: 0.0544); P(25 ≤ T ≤ 27) = 0.4452 (Z = 1.6036, Z = 0; exacta: 0.4456). | D9: ='Probabilidad'!$I$11 -> 0.9452
A10: f | B10: ¿Cuántas semanas permitirá una probabilidad del 90%, para concluir la ruta crítica a tiempo? | C10: Para 90 %: Z = 1.2816 → T = 26.5984; con tabla Z = 1.29 → T = 26.6089; duración a especificar: 27 semanas. | D10: ='Probabilidad'!$H$20 -> 27
A12: Procedencia de los datos
A13: Procedencia | B13: Actividades | C13: Campo
A14: Extraído del documento | B14: 9
A15: Inferido | B15: 0 | C15: A.predecessors, B.predecessors, C.predecessors, D.predecessors, E.predecessors, F.predecessors, G.predecessors, H.predecessors, I.predecessors
A17: Supuestos e inferencias
A18: Campo | B18: Valor | C18: Justificación | D18: Procedencia
A19: requested_outputs | B19: NETWORK_DIAGRAM | C19: Question 'a' asks for it. | D19: Inferido
A20: requested_outputs | B20: ACTIVITY_ESTIMATES | C20: Question 'b' asks for it. | D20: Inferido
A21: requested_outputs | B21: EARLY_LATE_TIMES | C21: Question 'c' asks for it. | D21: Inferido
A22: requested_outputs | B22: SLACK | C22: Question 'c' asks for it. | D22: Inferido
A23: requested_outputs | B23: CRITICAL_PATH | C23: Question 'd' asks for it. | D23: Inferido
A24: requested_outputs | B24: EXPECTED_DURATION | C24: Question 'd' asks for it. | D24: Inferido
A25: requested_outputs | B25: VARIANCE | C25: Question 'd' asks for it. | D25: Inferido
A26: requested_outputs | B26: PROBABILITY_QUERY | C26: Question 'e' asks for it. | D26: Inferido
A27: requested_outputs | B27: PERCENTILE_DURATION | C27: Question 'f' asks for it. | D27: Inferido
A28: calculation_method | B28: PERT | C28: Every activity has optimistic, most likely and pessimistic durations. | D28: Inferido
A30: Validación independiente de los cálculos
A31: Verificación | B31: ¿Correcta? | C31: Detalle
A32: network arcs match the activity predecessor lists | B32: Sí | C32: ok
A33: PERT t_e = a/6 + 2m/3 + b/6 and σ² = (b−a)²/36 | B33: Sí | C33: ok
A34: schedule: durations match their source | B34: Sí | C34: ok
A35: schedule: EF−ES = LF−LS = duration and LS−ES = LF−EF | B35: Sí | C35: ok
A36: schedule: every precedence respected | B36: Sí | C36: ok
A37: schedule: project duration = longest path (independent relaxation) | B37: Sí | C37: ok
A38: schedule: each critical path sums to the project duration | B38: Sí | C38: ok
A39: project variance re-summed from the raw estimates | B39: Sí | C39: ok
A40: probabilities re-derived by numerical integration of the normal pdf | B40: Sí | C40: ok
A41: percentile durations re-derived (Φ(Z) round-trip, table rule) | B41: Sí | C41: ok
A42: Gantt bars match ES→EF / LS→LF and critical flags | B42: Sí | C42: ok
