Workbook

Sheet Enunciado
A1: Taller 1 — Administración de proyectos
A2: Enunciado y datos de entrada
A4: Fuente | B4: TALLER 1 ADMINISTRACIÓN DE PROYECTOS.docx
A5: Unidad de tiempo | B5: semanas
A6: Método | B6: PERT (t_e = (a + b + 4m)/6 alimenta el CPM)
A7: options | B7: probability_method=exact; variance_strategy=max_variance_path
A9: Preguntas del ejercicio
A10: Parte | B10: Pregunta | C10: Salidas solicitadas
A11: a | B11: Elabore el diagrama Gantt | C11: Diagrama Gantt
A12: b | B12: Para cada actividad los tiempos de inicio más temprano, inicio más tardío, terminación más temprana, terminación más tardía y la holgura. | C12: Tiempos de inicio y terminación, Holguras
A13: c | B13: El tiempo mínimo esperado del proyecto, su varianza y las actividades de la ruta crítica. | C13: Ruta crítica, Duración del proyecto, Varianza del proyecto
A14: d | B14: La probabilidad de terminar el proyecto en 13 semanas o menos. | C14: Probabilidades de terminación
A15: e | B15: La probabilidad de terminar el proyecto en 16 semanas o más. | C15: Probabilidades de terminación
A16: f | B16: La probabilidad de desarrollar el proyecto entre 16 y 20 semanas. | C16: Probabilidades de terminación
A17: g | B17: Si se desea firmar un contrato que especifique el tiempo de terminación del proyecto de modo que haya una probabilidad del 98 % de cumplir la fecha deseada, ¿Qué duración debería especificarse en el contrato? | C17: Duración para una probabilidad objetivo
A19: Salidas solicitadas | B19: Diagrama Gantt, Tiempos de inicio y terminación, Holguras, Ruta crítica, Duración del proyecto, Varianza del proyecto, Probabilidades de terminación, Duración para una probabilidad objetivo
A21: Consultas de probabilidad
A22: id | B22: Tipo | C22: ≥ | D22: ≤ | E22: p | F22: Procedencia | G22: Fuente
A23: d | B23: AT_MOST | D23: 13 | F23: Inferido | G23: la probabilidad de terminar el proyecto en 13 semanas o menos.
A24: e | B24: AT_LEAST | C24: 16 | F24: Inferido | G24: la probabilidad de terminar el proyecto en 16 semanas o mas.
A25: f | B25: BETWEEN | C25: 16 | D25: 20 | F25: Inferido | G25: la probabilidad de desarrollar el proyecto entre 16 y 20 semanas.
A26: g | B26: PERCENTILE_TO_DURATION | E26: 0.98 | F26: Inferido | G26: Si se desea firmar un contrato que especifique el tiempo de terminación del proyecto de modo que haya una probabilidad del 98 % de cumplir la fecha deseada, ¿Qué duración debería especificarse en el contrato?
A28: Red original ACTIVIDAD - FLECHA y precedencias deducidas
A29: Actividad | B29: Nodo inicial | C29: Nodo final | D29: Predecesoras | E29: Vía ficticias | F29: Justificación
A30: A | B30: 1 | C30: 2 | D30: Ninguna | F30: La flecha A sale del nodo 1, al que no llega ninguna actividad: actividad inicial.
A31: B | B31: 2 | C31: 3 | D31: A | F31: La flecha B sale del nodo 2; llegan al nodo 2: A.
A32: C | B32: 2 | C32: 4 | D32: A | F32: La flecha C sale del nodo 2; llegan al nodo 2: A.
A33: D | B33: 3 | C33: 8 | D33: B | F33: La flecha D sale del nodo 3; llegan al nodo 3: B.
A34: E | B34: 8 | C34: 9 | D34: D | F34: La flecha E sale del nodo 8; llegan al nodo 8: D.
A35: F | B35: 4 | C35: 5 | D35: C, B | E35: ficticia_3_4 | F35: La flecha F sale del nodo 4; llegan al nodo 4: C; por la(s) ficticia(s) ficticia_3_4 también depende de B.
A36: G | B36: 4 | C36: 6 | D36: C, B | E36: ficticia_3_4 | F36: La flecha G sale del nodo 4; llegan al nodo 4: C; por la(s) ficticia(s) ficticia_3_4 también depende de B.
A37: H | B37: 5 | C37: 7 | D37: F | F37: La flecha H sale del nodo 5; llegan al nodo 5: F.
A38: I | B38: 6 | C38: 9 | D38: G, F | E38: ficticia_5_6 | F38: La flecha I sale del nodo 6; llegan al nodo 6: G; por la(s) ficticia(s) ficticia_5_6 también depende de F.
A39: J | B39: 7 | C39: 9 | D39: H | F39: La flecha J sale del nodo 7; llegan al nodo 7: H.
A41: Supuestos e inferencias
A42: Campo | B42: Valor | C42: Justificación | D42: Procedencia
A43: requested_outputs | B43: GANTT | C43: Question 'a' asks for it. | D43: Inferido
A44: requested_outputs | B44: EARLY_LATE_TIMES | C44: Question 'b' asks for it. | D44: Inferido
A45: requested_outputs | B45: SLACK | C45: Question 'b' asks for it. | D45: Inferido
A46: requested_outputs | B46: CRITICAL_PATH | C46: Question 'c' asks for it. | D46: Inferido
...

Sheet Datos
A1: Datos de las actividades
A2: Unidad de tiempo: semanas · Método: PERT (t_e = (a + b + 4m)/6 alimenta el CPM)
A4: Actividad | B4: Descripción | C4: Predecesoras | D4: Ficticia | E4: Optimista (a) | F4: Normal (m) | G4: Pesimista (b) | H4: Procedencia
A5: A | C5: Ninguna | D5: No | E5: 1 | F5: 2 | G5: 3 | H5: Extraído del documento (predecessors: Inferido)
A6: B | C6: A | D6: No | E6: 1 | F6: 3 | G6: 5 | H6: Extraído del documento (predecessors: Inferido)
A7: C | C7: A | D7: No | E7: 2 | F7: 3 | G7: 10 | H7: Extraído del documento (predecessors: Inferido)
A8: D | C8: B | D8: No | E8: 2 | F8: 5 | G8: 8 | H8: Extraído del documento (predecessors: Inferido)
A9: E | C9: D | D9: No | E9: 1 | F9: 2 | G9: 3 | H9: Extraído del documento (predecessors: Inferido)
A10: F | C10: C, B | D10: No | E10: 1 | F10: 1 | G10: 1 | H10: Extraído del documento (predecessors: Inferido)
A11: G | C11: C, B | D11: No | E11: 1 | F11: 1 | G11: 1 | H11: Extraído del documento (predecessors: Inferido)
A12: H | C12: F | D12: No | E12: 1 | F12: 3 | G12: 5 | H12: Extraído del documento (predecessors: Inferido)
A13: I | C13: G, F | D13: No | E13: 2 | F13: 4 | G13: 6 | H13: Extraído del documento (predecessors: Inferido)
A14: J | C14: H | D14: No | E14: 1 | F14: 5 | G14: 9 | H14: Extraído del documento (predecessors: Inferido)

Sheet PERT
A1: PERT probabilístico: tiempo esperado y varianza por actividad
A2: t_e = (a + b + 4m) / 6 σ² = [(b − a) / 6]²
A5: Actividad | B5: a | C5: m | D5: b | E5: t_e = (a + b + 4m)/6 | F5: σ² = [(b − a)/6]² | G5: t_e (fracción) | H5: σ² (fracción) | I5: Cálculo t_e | J5: Cálculo σ² | K5: ¿Crítica?
A6: A | B6: ='Datos'!$E$5 -> 1 | C6: ='Datos'!$F$5 -> 2 | D6: ='Datos'!$G$5 -> 3 | E6: =(B6+D6+4*C6)/6 -> 2 | F6: =((D6-B6)/6)^2 -> 0.11111111 | G6: 2 | H6: 1/9 | I6: (1 + 3 + 4·2) / 6 = 2 | J6: [(3 − 1) / 6]² = 1/9 | K6: ='CPM'!$L$6 -> Sí
A7: B | B7: ='Datos'!$E$6 -> 1 | C7: ='Datos'!$F$6 -> 3 | D7: ='Datos'!$G$6 -> 5 | E7: =(B7+D7+4*C7)/6 -> 3 | F7: =((D7-B7)/6)^2 -> 0.44444444 | G7: 3 | H7: 4/9 | I7: (1 + 5 + 4·3) / 6 = 3 | J7: [(5 − 1) / 6]² = 4/9 | K7: ='CPM'!$L$7 -> No
A8: C | B8: ='Datos'!$E$7 -> 2 | C8: ='Datos'!$F$7 -> 3 | D8: ='Datos'!$G$7 -> 10 | E8: =(B8+D8+4*C8)/6 -> 4 | F8: =((D8-B8)/6)^2 -> 1.7777778 | G8: 4 | H8: 16/9 | I8: (2 + 10 + 4·3) / 6 = 4 | J8: [(10 − 2) / 6]² = 16/9 | K8: ='CPM'!$L$8 -> Sí
A9: D | B9: ='Datos'!$E$8 -> 2 | C9: ='Datos'!$F$8 -> 5 | D9: ='Datos'!$G$8 -> 8 | E9: =(B9+D9+4*C9)/6 -> 5 | F9: =((D9-B9)/6)^2 -> 1 | G9: 5 | H9: 1 | I9: (2 + 8 + 4·5) / 6 = 5 | J9: [(8 − 2) / 6]² = 1 | K9: ='CPM'!$L$9 -> No
A10: E | B10: ='Datos'!$E$9 -> 1 | C10: ='Datos'!$F$9 -> 2 | D10: ='Datos'!$G$9 -> 3 | E10: =(B10+D10+4*C10)/6 -> 2 | F10: =((D10-B10)/6)^2 -> 0.11111111 | G10: 2 | H10: 1/9 | I10: (1 + 3 + 4·2) / 6 = 2 | J10: [(3 − 1) / 6]² = 1/9 | K10: ='CPM'!$L$10 -> No
A11: F | B11: ='Datos'!$E$10 -> 1 | C11: ='Datos'!$F$10 -> 1 | D11: ='Datos'!$G$10 -> 1 | E11: =(B11+D11+4*C11)/6 -> 1 | F11: =((D11-B11)/6)^2 -> 0 | G11: 1 | H11: 0 | I11: (1 + 1 + 4·1) / 6 = 1 | J11: [(1 − 1) / 6]² = 0 | K11: ='CPM'!$L$11 -> Sí
A12: G | B12: ='Datos'!$E$11 -> 1 | C12: ='Datos'!$F$11 -> 1 | D12: ='Datos'!$G$11 -> 1 | E12: =(B12+D12+4*C12)/6 -> 1 | F12: =((D12-B12)/6)^2 -> 0 | G12: 1 | H12: 0 | I12: (1 + 1 + 4·1) / 6 = 1 | J12: [(1 − 1) / 6]² = 0 | K12: ='CPM'!$L$12 -> No
A13: H | B13: ='Datos'!$E$12 -> 1 | C13: ='Datos'!$F$12 -> 3 | D13: ='Datos'!$G$12 -> 5 | E13: =(B13+D13+4*C13)/6 -> 3 | F13: =((D13-B13)/6)^2 -> 0.44444444 | G13: 3 | H13: 4/9 | I13: (1 + 5 + 4·3) / 6 = 3 | J13: [(5 − 1) / 6]² = 4/9 | K13: ='CPM'!$L$13 -> Sí
A14: I | B14: ='Datos'!$E$13 -> 2 | C14: ='Datos'!$F$13 -> 4 | D14: ='Datos'!$G$13 -> 6 | E14: =(B14+D14+4*C14)/6 -> 4 | F14: =((D14-B14)/6)^2 -> 0.44444444 | G14: 4 | H14: 4/9 | I14: (2 + 6 + 4·4) / 6 = 4 | J14: [(6 − 2) / 6]² = 4/9 | K14: ='CPM'!$L$14 -> No
A15: J | B15: ='Datos'!$E$14 -> 1 | C15: ='Datos'!$F$14 -> 5 | D15: ='Datos'!$G$14 -> 9 | E15: =(B15+D15+4*C15)/6 -> 5 | F15: =((D15-B15)/6)^2 -> 1.7777778 | G15: 5 | H15: 16/9 | I15: (1 + 9 + 4·5) / 6 = 5 | J15: [(9 − 1) / 6]² = 16/9 | K15: ='CPM'!$L$15 -> Sí
A17: Ruta crítica utilizada | E17: A – C – F – H – J
A18: Varianza del proyecto σ² = Σ σ² de las actividades críticas | F18: =F6+F8+F11+F13+F15 -> 4.1111111 | G18: 37/9 | I18: σ² = 1/9 + 16/9 + 0 + 4/9 + 16/9 = 37/9
A19: Desviación estándar σ = √(Σ σ² A.C.) | F19: =SQRT(F18) -> 2.0275875 | I19: σ = √(37/9) = 2.0276
A20: Tiempo esperado mínimo del proyecto (t_e) | E20: ='CPM'!$D$2 -> 15

Sheet CPM
A1: Método de la ruta crítica — duraciones = tiempo esperado t_e
A2: Tiempo esperado mínimo del proyecto (t_e) (semanas) | D2: =MAX(F10,F14,F15) -> 15
A3: Ruta crítica | D3: A – C – F – H – J
A5: Actividad | B5: Predecesoras | C5: Sucesoras | D5: Duración (t_e) | E5: Inicio más temprano (IC) | F5: Terminación más temprana (TC) | G5: Inicio más tardío (IL) | H5: Terminación más tardía (TL) | I5: Holgura (IL − IC) | J5: Holgura (TL − TC) | K5: Holgura libre | L5: ¿Crítica?
A6: A | B6: — | C6: B, C | D6: ='PERT'!$E$6 -> 2 | E6: 0 | F6: =E6+D6 -> 2 | G6: =H6-D6 -> 0 | H6: =MIN(G7,G8) -> 2 | I6: =ROUND(G6-E6,10) -> 0 | J6: =ROUND(H6-F6,10) -> 0 | K6: =ROUND(MIN(E7,E8)-F6,10) -> 0 | L6: =IF(ABS(I6)<0.000000001,"Sí","No") -> Sí
A7: B | B7: A | C7: D, F, G | D7: ='PERT'!$E$7 -> 3 | E7: =MAX(F6) -> 2 | F7: =E7+D7 -> 5 | G7: =H7-D7 -> 3 | H7: =MIN(G9,G11,G12) -> 6 | I7: =ROUND(G7-E7,10) -> 1 | J7: =ROUND(H7-F7,10) -> 1 | K7: =ROUND(MIN(E9,E11,E12)-F7,10) -> 0 | L7: =IF(ABS(I7)<0.000000001,"Sí","No") -> No
A8: C | B8: A | C8: F, G | D8: ='PERT'!$E$8 -> 4 | E8: =MAX(F6) -> 2 | F8: =E8+D8 -> 6 | G8: =H8-D8 -> 2 | H8: =MIN(G11,G12) -> 6 | I8: =ROUND(G8-E8,10) -> 0 | J8: =ROUND(H8-F8,10) -> 0 | K8: =ROUND(MIN(E11,E12)-F8,10) -> 0 | L8: =IF(ABS(I8)<0.000000001,"Sí","No") -> Sí
A9: D | B9: B | C9: E | D9: ='PERT'!$E$9 -> 5 | E9: =MAX(F7) -> 5 | F9: =E9+D9 -> 10 | G9: =H9-D9 -> 8 | H9: =MIN(G10) -> 13 | I9: =ROUND(G9-E9,10) -> 3 | J9: =ROUND(H9-F9,10) -> 3 | K9: =ROUND(MIN(E10)-F9,10) -> 0 | L9: =IF(ABS(I9)<0.000000001,"Sí","No") -> No
A10: E | B10: D | C10: — | D10: ='PERT'!$E$10 -> 2 | E10: =MAX(F9) -> 10 | F10: =E10+D10 -> 12 | G10: =H10-D10 -> 13 | H10: =$D$2 -> 15 | I10: =ROUND(G10-E10,10) -> 3 | J10: =ROUND(H10-F10,10) -> 3 | K10: =ROUND($D$2-F10,10) -> 3 | L10: =IF(ABS(I10)<0.000000001,"Sí","No") -> No
A11: F | B11: C, B | C11: H, I | D11: ='PERT'!$E$11 -> 1 | E11: =MAX(F8,F7) -> 6 | F11: =E11+D11 -> 7 | G11: =H11-D11 -> 6 | H11: =MIN(G13,G14) -> 7 | I11: =ROUND(G11-E11,10) -> 0 | J11: =ROUND(H11-F11,10) -> 0 | K11: =ROUND(MIN(E13,E14)-F11,10) -> 0 | L11: =IF(ABS(I11)<0.000000001,"Sí","No") -> Sí
A12: G | B12: C, B | C12: I | D12: ='PERT'!$E$12 -> 1 | E12: =MAX(F8,F7) -> 6 | F12: =E12+D12 -> 7 | G12: =H12-D12 -> 10 | H12: =MIN(G14) -> 11 | I12: =ROUND(G12-E12,10) -> 4 | J12: =ROUND(H12-F12,10) -> 4 | K12: =ROUND(MIN(E14)-F12,10) -> 0 | L12: =IF(ABS(I12)<0.000000001,"Sí","No") -> No
A13: H | B13: F | C13: J | D13: ='PERT'!$E$13 -> 3 | E13: =MAX(F11) -> 7 | F13: =E13+D13 -> 10 | G13: =H13-D13 -> 7 | H13: =MIN(G15) -> 10 | I13: =ROUND(G13-E13,10) -> 0 | J13: =ROUND(H13-F13,10) -> 0 | K13: =ROUND(MIN(E15)-F13,10) -> 0 | L13: =IF(ABS(I13)<0.000000001,"Sí","No") -> Sí
A14: I | B14: G, F | C14: — | D14: ='PERT'!$E$14 -> 4 | E14: =MAX(F12,F11) -> 7 | F14: =E14+D14 -> 11 | G14: =H14-D14 -> 11 | H14: =$D$2 -> 15 | I14: =ROUND(G14-E14,10) -> 4 | J14: =ROUND(H14-F14,10) -> 4 | K14: =ROUND($D$2-F14,10) -> 4 | L14: =IF(ABS(I14)<0.000000001,"Sí","No") -> No
A15: J | B15: H | C15: — | D15: ='PERT'!$E$15 -> 5 | E15: =MAX(F13) -> 10 | F15: =E15+D15 -> 15 | G15: =H15-D15 -> 10 | H15: =$D$2 -> 15 | I15: =ROUND(G15-E15,10) -> 0 | J15: =ROUND(H15-F15,10) -> 0 | K15: =ROUND($D$2-F15,10) -> 0 | L15: =IF(ABS(I15)<0.000000001,"Sí","No") -> Sí
A17: Holgura = IL − IC = TL − TC; actividades con holgura 0 = ruta crítica. IC = máx(TC de predecesoras); TL = mín(IL de sucesoras).

Sheet Gantt
A1: Diagrama Gantt
A2: Por actividad: 1.ª fila = inicio más temprano → terminación más temprana; 2.ª fila = inicio más tardío → terminación más tardía.
A4: Actividades | B4: Fila | C4: Inicio | D4: Fin | E4: Holgura | F4: Duración en semanas | U4: Observaciones
F5: 1 | G5: 2 | H5: 3 | I5: 4 | J5: 5 | K5: 6 | L5: 7 | M5: 8 | N5: 9 | O5: 10 | P5: 11 | Q5: 12 | R5: 13 | S5: 14 | T5: 15
A6: A | B6: Temprana | C6: ='CPM'!$E$6 -> 0 | D6: ='CPM'!$F$6 -> 2 | E6: ='CPM'!$I$6 -> 0 | F6: =IF(AND(ROUND($D6,9)>ROUND($C6,9),F$5>ROUND($C6,9),F$5-1<ROUND($D6,9)),"█","") -> █ | G6: =IF(AND(ROUND($D6,9)>ROUND($C6,9),G$5>ROUND($C6,9),G$5-1<ROUND($D6,9)),"█","") -> █ | H6: =IF(AND(ROUND($D6,9)>ROUND($C6,9),H$5>ROUND($C6,9),H$5-1<ROUND($D6,9)),"█","") | I6: =IF(AND(ROUND($D6,9)>ROUND($C6,9),I$5>ROUND($C6,9),I$5-1<ROUND($D6,9)),"█","") | J6: =IF(AND(ROUND($D6,9)>ROUND($C6,9),J$5>ROUND($C6,9),J$5-1<ROUND($D6,9)),"█","") | K6: =IF(AND(ROUND($D6,9)>ROUND($C6,9),K$5>ROUND($C6,9),K$5-1<ROUND($D6,9)),"█","") | L6: =IF(AND(ROUND($D6,9)>ROUND($C6,9),L$5>ROUND($C6,9),L$5-1<ROUND($D6,9)),"█","") | M6: =IF(AND(ROUND($D6,9)>ROUND($C6,9),M$5>ROUND($C6,9),M$5-1<ROUND($D6,9)),"█","") | ... T6: =IF(AND(ROUND($D6,9)>ROUND($C6,9),T$5>ROUND($C6,9),T$5-1<ROUND($D6,9)),"█","") | U6: =IF(ABS($E$6)<0.000000001,"Actividad Crítica","Holgura de "&ROUND($E$6,4)&" "&IF(ROUND($E$6,4)=1,"semana","semanas")) -> Actividad Crítica
B7: Tardía | C7: ='CPM'!$G$6 -> 0 | D7: ='CPM'!$H$6 -> 2 | F7: =IF(AND(ROUND($D7,9)>ROUND($C7,9),F$5>ROUND($C7,9),F$5-1<ROUND($D7,9)),"█","") -> █ | G7: =IF(AND(ROUND($D7,9)>ROUND($C7,9),G$5>ROUND($C7,9),G$5-1<ROUND($D7,9)),"█","") -> █ | H7: =IF(AND(ROUND($D7,9)>ROUND($C7,9),H$5>ROUND($C7,9),H$5-1<ROUND($D7,9)),"█","") | I7: =IF(AND(ROUND($D7,9)>ROUND($C7,9),I$5>ROUND($C7,9),I$5-1<ROUND($D7,9)),"█","") | J7: =IF(AND(ROUND($D7,9)>ROUND($C7,9),J$5>ROUND($C7,9),J$5-1<ROUND($D7,9)),"█","") | K7: =IF(AND(ROUND($D7,9)>ROUND($C7,9),K$5>ROUND($C7,9),K$5-1<ROUND($D7,9)),"█","") | L7: =IF(AND(ROUND($D7,9)>ROUND($C7,9),L$5>ROUND($C7,9),L$5-1<ROUND($D7,9)),"█","") | M7: =IF(AND(ROUND($D7,9)>ROUND($C7,9),M$5>ROUND($C7,9),M$5-1<ROUND($D7,9)),"█","") | ... T7: =IF(AND(ROUND($D7,9)>ROUND($C7,9),T$5>ROUND($C7,9),T$5-1<ROUND($D7,9)),"█","")
A8: B | B8: Temprana | C8: ='CPM'!$E$7 -> 2 | D8: ='CPM'!$F$7 -> 5 | E8: ='CPM'!$I$7 -> 1 | F8: =IF(AND(ROUND($D8,9)>ROUND($C8,9),F$5>ROUND($C8,9),F$5-1<ROUND($D8,9)),"█","") | G8: =IF(AND(ROUND($D8,9)>ROUND($C8,9),G$5>ROUND($C8,9),G$5-1<ROUND($D8,9)),"█","") | H8: =IF(AND(ROUND($D8,9)>ROUND($C8,9),H$5>ROUND($C8,9),H$5-1<ROUND($D8,9)),"█","") -> █ | I8: =IF(AND(ROUND($D8,9)>ROUND($C8,9),I$5>ROUND($C8,9),I$5-1<ROUND($D8,9)),"█","") -> █ | J8: =IF(AND(ROUND($D8,9)>ROUND($C8,9),J$5>ROUND($C8,9),J$5-1<ROUND($D8,9)),"█","") -> █ | K8: =IF(AND(ROUND($D8,9)>ROUND($C8,9),K$5>ROUND($C8,9),K$5-1<ROUND($D8,9)),"█","") | L8: =IF(AND(ROUND($D8,9)>ROUND($C8,9),L$5>ROUND($C8,9),L$5-1<ROUND($D8,9)),"█","") | M8: =IF(AND(ROUND($D8,9)>ROUND($C8,9),M$5>ROUND($C8,9),M$5-1<ROUND($D8,9)),"█","") | ... T8: =IF(AND(ROUND($D8,9)>ROUND($C8,9),T$5>ROUND($C8,9),T$5-1<ROUND($D8,9)),"█","") | U8: =IF(ABS($E$8)<0.000000001,"Actividad Crítica","Holgura de "&ROUND($E$8,4)&" "&IF(ROUND($E$8,4)=1,"semana","semanas")) -> Holgura de 1 semana
B9: Tardía | C9: ='CPM'!$G$7 -> 3 | D9: ='CPM'!$H$7 -> 6 | F9: =IF(AND(ROUND($D9,9)>ROUND($C9,9),F$5>ROUND($C9,9),F$5-1<ROUND($D9,9)),"█","") | G9: =IF(AND(ROUND($D9,9)>ROUND($C9,9),G$5>ROUND($C9,9),G$5-1<ROUND($D9,9)),"█","") | H9: =IF(AND(ROUND($D9,9)>ROUND($C9,9),H$5>ROUND($C9,9),H$5-1<ROUND($D9,9)),"█","") | I9: =IF(AND(ROUND($D9,9)>ROUND($C9,9),I$5>ROUND($C9,9),I$5-1<ROUND($D9,9)),"█","") -> █ | J9: =IF(AND(ROUND($D9,9)>ROUND($C9,9),J$5>ROUND($C9,9),J$5-1<ROUND($D9,9)),"█","") -> █ | K9: =IF(AND(ROUND($D9,9)>ROUND($C9,9),K$5>ROUND($C9,9),K$5-1<ROUND($D9,9)),"█","") -> █ | L9: =IF(AND(ROUND($D9,9)>ROUND($C9,9),L$5>ROUND($C9,9),L$5-1<ROUND($D9,9)),"█","") | M9: =IF(AND(ROUND($D9,9)>ROUND($C9,9),M$5>ROUND($C9,9),M$5-1<ROUND($D9,9)),"█","") | ... T9: =IF(AND(ROUND($D9,9)>ROUND($C9,9),T$5>ROUND($C9,9),T$5-1<ROUND($D9,9)),"█","")
A10: C | B10: Temprana | C10: ='CPM'!$E$8 -> 2 | D10: ='CPM'!$F$8 -> 6 | E10: ='CPM'!$I$8 -> 0 | F10: =IF(AND(ROUND($D10,9)>ROUND($C10,9),F$5>ROUND($C10,9),F$5-1<ROUND($D10,9)),"█","") | G10: =IF(AND(ROUND($D10,9)>ROUND($C10,9),G$5>ROUND($C10,9),G$5-1<ROUND($D10,9)),"█","") | H10: =IF(AND(ROUND($D10,9)>ROUND($C10,9),H$5>ROUND($C10,9),H$5-1<ROUND($D10,9)),"█","") -> █ | I10: =IF(AND(ROUND($D10,9)>ROUND($C10,9),I$5>ROUND($C10,9),I$5-1<ROUND($D10,9)),"█","") -> █ | J10: =IF(AND(ROUND($D10,9)>ROUND($C10,9),J$5>ROUND($C10,9),J$5-1<ROUND($D10,9)),"█","") -> █ | K10: =IF(AND(ROUND($D10,9)>ROUND($C10,9),K$5>ROUND($C10,9),K$5-1<ROUND($D10,9)),"█","") -> █ | L10: =IF(AND(ROUND($D10,9)>ROUND($C10,9),L$5>ROUND($C10,9),L$5-1<ROUND($D10,9)),"█","") | M10: =IF(AND(ROUND($D10,9)>ROUND($C10,9),M$5>ROUND($C10,9),M$5-1<ROUND($D10,9)),"█","") | ... T10: =IF(AND(ROUND($D10,9)>ROUND($C10,9),T$5>ROUND($C10,9),T$5-1<ROUND($D10,9)),"█","") | U10: =IF(ABS($E$10)<0.000000001,"Actividad Crítica","Holgura de "&ROUND($E$10,4)&" "&IF(ROUND($E$10,4)=1,"semana","semanas")) -> Actividad Crítica
B11: Tardía | C11: ='CPM'!$G$8 -> 2 | D11: ='CPM'!$H$8 -> 6 | F11: =IF(AND(ROUND($D11,9)>ROUND($C11,9),F$5>ROUND($C11,9),F$5-1<ROUND($D11,9)),"█","") | G11: =IF(AND(ROUND($D11,9)>ROUND($C11,9),G$5>ROUND($C11,9),G$5-1<ROUND($D11,9)),"█","") | H11: =IF(AND(ROUND($D11,9)>ROUND($C11,9),H$5>ROUND($C11,9),H$5-1<ROUND($D11,9)),"█","") -> █ | I11: =IF(AND(ROUND($D11,9)>ROUND($C11,9),I$5>ROUND($C11,9),I$5-1<ROUND($D11,9)),"█","") -> █ | J11: =IF(AND(ROUND($D11,9)>ROUND($C11,9),J$5>ROUND($C11,9),J$5-1<ROUND($D11,9)),"█","") -> █ | K11: =IF(AND(ROUND($D11,9)>ROUND($C11,9),K$5>ROUND($C11,9),K$5-1<ROUND($D11,9)),"█","") -> █ | L11: =IF(AND(ROUND($D11,9)>ROUND($C11,9),L$5>ROUND($C11,9),L$5-1<ROUND($D11,9)),"█","") | M11: =IF(AND(ROUND($D11,9)>ROUND($C11,9),M$5>ROUND($C11,9),M$5-1<ROUND($D11,9)),"█","") | ... T11: =IF(AND(ROUND($D11,9)>ROUND($C11,9),T$5>ROUND($C11,9),T$5-1<ROUND($D11,9)),"█","")
A12: D | B12: Temprana | C12: ='CPM'!$E$9 -> 5 | D12: ='CPM'!$F$9 -> 10 | E12: ='CPM'!$I$9 -> 3 | F12: =IF(AND(ROUND($D12,9)>ROUND($C12,9),F$5>ROUND($C12,9),F$5-1<ROUND($D12,9)),"█","") | G12: =IF(AND(ROUND($D12,9)>ROUND($C12,9),G$5>ROUND($C12,9),G$5-1<ROUND($D12,9)),"█","") | H12: =IF(AND(ROUND($D12,9)>ROUND($C12,9),H$5>ROUND($C12,9),H$5-1<ROUND($D12,9)),"█","") | I12: =IF(AND(ROUND($D12,9)>ROUND($C12,9),I$5>ROUND($C12,9),I$5-1<ROUND($D12,9)),"█","") | J12: =IF(AND(ROUND($D12,9)>ROUND($C12,9),J$5>ROUND($C12,9),J$5-1<ROUND($D12,9)),"█","") | K12: =IF(AND(ROUND($D12,9)>ROUND($C12,9),K$5>ROUND($C12,9),K$5-1<ROUND($D12,9)),"█","") -> █ | L12: =IF(AND(ROUND($D12,9)>ROUND($C12,9),L$5>ROUND($C12,9),L$5-1<ROUND($D12,9)),"█","") -> █ | M12: =IF(AND(ROUND($D12,9)>ROUND($C12,9),M$5>ROUND($C12,9),M$5-1<ROUND($D12,9)),"█","") -> █ | ... T12: =IF(AND(ROUND($D12,9)>ROUND($C12,9),T$5>ROUND($C12,9),T$5-1<ROUND($D12,9)),"█","") | U12: =IF(ABS($E$12)<0.000000001,"Actividad Crítica","Holgura de "&ROUND($E$12,4)&" "&IF(ROUND($E$12,4)=1,"semana","semanas")) -> Holgura de 3 semanas
B13: Tardía | C13: ='CPM'!$G$9 -> 8 | D13: ='CPM'!$H$9 -> 13 | F13: =IF(AND(ROUND($D13,9)>ROUND($C13,9),F$5>ROUND($C13,9),F$5-1<ROUND($D13,9)),"█","") | G13: =IF(AND(ROUND($D13,9)>ROUND($C13,9),G$5>ROUND($C13,9),G$5-1<ROUND($D13,9)),"█","") | H13: =IF(AND(ROUND($D13,9)>ROUND($C13,9),H$5>ROUND($C13,9),H$5-1<ROUND($D13,9)),"█","") | I13: =IF(AND(ROUND($D13,9)>ROUND($C13,9),I$5>ROUND($C13,9),I$5-1<ROUND($D13,9)),"█","") | J13: =IF(AND(ROUND($D13,9)>ROUND($C13,9),J$5>ROUND($C13,9),J$5-1<ROUND($D13,9)),"█","") | K13: =IF(AND(ROUND($D13,9)>ROUND($C13,9),K$5>ROUND($C13,9),K$5-1<ROUND($D13,9)),"█","") | L13: =IF(AND(ROUND($D13,9)>ROUND($C13,9),L$5>ROUND($C13,9),L$5-1<ROUND($D13,9)),"█","") | M13: =IF(AND(ROUND($D13,9)>ROUND($C13,9),M$5>ROUND($C13,9),M$5-1<ROUND($D13,9)),"█","") | ... T13: =IF(AND(ROUND($D13,9)>ROUND($C13,9),T$5>ROUND($C13,9),T$5-1<ROUND($D13,9)),"█","")
A14: E | B14: Temprana | C14: ='CPM'!$E$10 -> 10 | D14: ='CPM'!$F$10 -> 12 | E14: ='CPM'!$I$10 -> 3 | F14: =IF(AND(ROUND($D14,9)>ROUND($C14,9),F$5>ROUND($C14,9),F$5-1<ROUND($D14,9)),"█","") | G14: =IF(AND(ROUND($D14,9)>ROUND($C14,9),G$5>ROUND($C14,9),G$5-1<ROUND($D14,9)),"█","") | H14: =IF(AND(ROUND($D14,9)>ROUND($C14,9),H$5>ROUND($C14,9),H$5-1<ROUND($D14,9)),"█","") | I14: =IF(AND(ROUND($D14,9)>ROUND($C14,9),I$5>ROUND($C14,9),I$5-1<ROUND($D14,9)),"█","") | J14: =IF(AND(ROUND($D14,9)>ROUND($C14,9),J$5>ROUND($C14,9),J$5-1<ROUND($D14,9)),"█","") | K14: =IF(AND(ROUND($D14,9)>ROUND($C14,9),K$5>ROUND($C14,9),K$5-1<ROUND($D14,9)),"█","") | L14: =IF(AND(ROUND($D14,9)>ROUND($C14,9),L$5>ROUND($C14,9),L$5-1<ROUND($D14,9)),"█","") | M14: =IF(AND(ROUND($D14,9)>ROUND($C14,9),M$5>ROUND($C14,9),M$5-1<ROUND($D14,9)),"█","") | ... T14: =IF(AND(ROUND($D14,9)>ROUND($C14,9),T$5>ROUND($C14,9),T$5-1<ROUND($D14,9)),"█","") | U14: =IF(ABS($E$14)<0.000000001,"Actividad Crítica","Holgura de "&ROUND($E$14,4)&" "&IF(ROUND($E$14,4)=1,"semana","semanas")) -> Holgura de 3 semanas
B15: Tardía | C15: ='CPM'!$G$10 -> 13 | D15: ='CPM'!$H$10 -> 15 | F15: =IF(AND(ROUND($D15,9)>ROUND($C15,9),F$5>ROUND($C15,9),F$5-1<ROUND($D15,9)),"█","") | G15: =IF(AND(ROUND($D15,9)>ROUND($C15,9),G$5>ROUND($C15,9),G$5-1<ROUND($D15,9)),"█","") | H15: =IF(AND(ROUND($D15,9)>ROUND($C15,9),H$5>ROUND($C15,9),H$5-1<ROUND($D15,9)),"█","") | I15: =IF(AND(ROUND($D15,9)>ROUND($C15,9),I$5>ROUND($C15,9),I$5-1<ROUND($D15,9)),"█","") | J15: =IF(AND(ROUND($D15,9)>ROUND($C15,9),J$5>ROUND($C15,9),J$5-1<ROUND($D15,9)),"█","") | K15: =IF(AND(ROUND($D15,9)>ROUND($C15,9),K$5>ROUND($C15,9),K$5-1<ROUND($D15,9)),"█","") | L15: =IF(AND(ROUND($D15,9)>ROUND($C15,9),L$5>ROUND($C15,9),L$5-1<ROUND($D15,9)),"█","") | M15: =IF(AND(ROUND($D15,9)>ROUND($C15,9),M$5>ROUND($C15,9),M$5-1<ROUND($D15,9)),"█","") | ... T15: =IF(AND(ROUND($D15,9)>ROUND($C15,9),T$5>ROUND($C15,9),T$5-1<ROUND($D15,9)),"█","") -> █
A16: F | B16: Temprana | C16: ='CPM'!$E$11 -> 6 | D16: ='CPM'!$F$11 -> 7 | E16: ='CPM'!$I$11 -> 0 | F16: =IF(AND(ROUND($D16,9)>ROUND($C16,9),F$5>ROUND($C16,9),F$5-1<ROUND($D16,9)),"█","") | G16: =IF(AND(ROUND($D16,9)>ROUND($C16,9),G$5>ROUND($C16,9),G$5-1<ROUND($D16,9)),"█","") | H16: =IF(AND(ROUND($D16,9)>ROUND($C16,9),H$5>ROUND($C16,9),H$5-1<ROUND($D16,9)),"█","") | I16: =IF(AND(ROUND($D16,9)>ROUND($C16,9),I$5>ROUND($C16,9),I$5-1<ROUND($D16,9)),"█","") | J16: =IF(AND(ROUND($D16,9)>ROUND($C16,9),J$5>ROUND($C16,9),J$5-1<ROUND($D16,9)),"█","") | K16: =IF(AND(ROUND($D16,9)>ROUND($C16,9),K$5>ROUND($C16,9),K$5-1<ROUND($D16,9)),"█","") | L16: =IF(AND(ROUND($D16,9)>ROUND($C16,9),L$5>ROUND($C16,9),L$5-1<ROUND($D16,9)),"█","") -> █ | M16: =IF(AND(ROUND($D16,9)>ROUND($C16,9),M$5>ROUND($C16,9),M$5-1<ROUND($D16,9)),"█","") | ... T16: =IF(AND(ROUND($D16,9)>ROUND($C16,9),T$5>ROUND($C16,9),T$5-1<ROUND($D16,9)),"█","") | U16: =IF(ABS($E$16)<0.000000001,"Actividad Crítica","Holgura de "&ROUND($E$16,4)&" "&IF(ROUND($E$16,4)=1,"semana","semanas")) -> Actividad Crítica
B17: Tardía | C17: ='CPM'!$G$11 -> 6 | D17: ='CPM'!$H$11 -> 7 | F17: =IF(AND(ROUND($D17,9)>ROUND($C17,9),F$5>ROUND($C17,9),F$5-1<ROUND($D17,9)),"█","") | G17: =IF(AND(ROUND($D17,9)>ROUND($C17,9),G$5>ROUND($C17,9),G$5-1<ROUND($D17,9)),"█","") | H17: =IF(AND(ROUND($D17,9)>ROUND($C17,9),H$5>ROUND($C17,9),H$5-1<ROUND($D17,9)),"█","") | I17: =IF(AND(ROUND($D17,9)>ROUND($C17,9),I$5>ROUND($C17,9),I$5-1<ROUND($D17,9)),"█","") | J17: =IF(AND(ROUND($D17,9)>ROUND($C17,9),J$5>ROUND($C17,9),J$5-1<ROUND($D17,9)),"█","") | K17: =IF(AND(ROUND($D17,9)>ROUND($C17,9),K$5>ROUND($C17,9),K$5-1<ROUND($D17,9)),"█","") | L17: =IF(AND(ROUND($D17,9)>ROUND($C17,9),L$5>ROUND($C17,9),L$5-1<ROUND($D17,9)),"█","") -> █ | M17: =IF(AND(ROUND($D17,9)>ROUND($C17,9),M$5>ROUND($C17,9),M$5-1<ROUND($D17,9)),"█","") | ... T17: =IF(AND(ROUND($D17,9)>ROUND($C17,9),T$5>ROUND($C17,9),T$5-1<ROUND($D17,9)),"█","")
A18: G | B18: Temprana | C18: ='CPM'!$E$12 -> 6 | D18: ='CPM'!$F$12 -> 7 | E18: ='CPM'!$I$12 -> 4 | F18: =IF(AND(ROUND($D18,9)>ROUND($C18,9),F$5>ROUND($C18,9),F$5-1<ROUND($D18,9)),"█","") | G18: =IF(AND(ROUND($D18,9)>ROUND($C18,9),G$5>ROUND($C18,9),G$5-1<ROUND($D18,9)),"█","") | H18: =IF(AND(ROUND($D18,9)>ROUND($C18,9),H$5>ROUND($C18,9),H$5-1<ROUND($D18,9)),"█","") | I18: =IF(AND(ROUND($D18,9)>ROUND($C18,9),I$5>ROUND($C18,9),I$5-1<ROUND($D18,9)),"█","") | J18: =IF(AND(ROUND($D18,9)>ROUND($C18,9),J$5>ROUND($C18,9),J$5-1<ROUND($D18,9)),"█","") | K18: =IF(AND(ROUND($D18,9)>ROUND($C18,9),K$5>ROUND($C18,9),K$5-1<ROUND($D18,9)),"█","") | L18: =IF(AND(ROUND($D18,9)>ROUND($C18,9),L$5>ROUND($C18,9),L$5-1<ROUND($D18,9)),"█","") -> █ | M18: =IF(AND(ROUND($D18,9)>ROUND($C18,9),M$5>ROUND($C18,9),M$5-1<ROUND($D18,9)),"█","") | ... T18: =IF(AND(ROUND($D18,9)>ROUND($C18,9),T$5>ROUND($C18,9),T$5-1<ROUND($D18,9)),"█","") | U18: =IF(ABS($E$18)<0.000000001,"Actividad Crítica","Holgura de "&ROUND($E$18,4)&" "&IF(ROUND($E$18,4)=1,"semana","semanas")) -> Holgura de 4 semanas
B19: Tardía | C19: ='CPM'!$G$12 -> 10 | D19: ='CPM'!$H$12 -> 11 | F19: =IF(AND(ROUND($D19,9)>ROUND($C19,9),F$5>ROUND($C19,9),F$5-1<ROUND($D19,9)),"█","") | G19: =IF(AND(ROUND($D19,9)>ROUND($C19,9),G$5>ROUND($C19,9),G$5-1<ROUND($D19,9)),"█","") | H19: =IF(AND(ROUND($D19,9)>ROUND($C19,9),H$5>ROUND($C19,9),H$5-1<ROUND($D19,9)),"█","") | I19: =IF(AND(ROUND($D19,9)>ROUND($C19,9),I$5>ROUND($C19,9),I$5-1<ROUND($D19,9)),"█","") | J19: =IF(AND(ROUND($D19,9)>ROUND($C19,9),J$5>ROUND($C19,9),J$5-1<ROUND($D19,9)),"█","") | K19: =IF(AND(ROUND($D19,9)>ROUND($C19,9),K$5>ROUND($C19,9),K$5-1<ROUND($D19,9)),"█","") | L19: =IF(AND(ROUND($D19,9)>ROUND($C19,9),L$5>ROUND($C19,9),L$5-1<ROUND($D19,9)),"█","") | M19: =IF(AND(ROUND($D19,9)>ROUND($C19,9),M$5>ROUND($C19,9),M$5-1<ROUND($D19,9)),"█","") | ... T19: =IF(AND(ROUND($D19,9)>ROUND($C19,9),T$5>ROUND($C19,9),T$5-1<ROUND($D19,9)),"█","")
A20: H | B20: Temprana | C20: ='CPM'!$E$13 -> 7 | D20: ='CPM'!$F$13 -> 10 | E20: ='CPM'!$I$13 -> 0 | F20: =IF(AND(ROUND($D20,9)>ROUND($C20,9),F$5>ROUND($C20,9),F$5-1<ROUND($D20,9)),"█","") | G20: =IF(AND(ROUND($D20,9)>ROUND($C20,9),G$5>ROUND($C20,9),G$5-1<ROUND($D20,9)),"█","") | H20: =IF(AND(ROUND($D20,9)>ROUND($C20,9),H$5>ROUND($C20,9),H$5-1<ROUND($D20,9)),"█","") | I20: =IF(AND(ROUND($D20,9)>ROUND($C20,9),I$5>ROUND($C20,9),I$5-1<ROUND($D20,9)),"█","") | J20: =IF(AND(ROUND($D20,9)>ROUND($C20,9),J$5>ROUND($C20,9),J$5-1<ROUND($D20,9)),"█","") | K20: =IF(AND(ROUND($D20,9)>ROUND($C20,9),K$5>ROUND($C20,9),K$5-1<ROUND($D20,9)),"█","") | L20: =IF(AND(ROUND($D20,9)>ROUND($C20,9),L$5>ROUND($C20,9),L$5-1<ROUND($D20,9)),"█","") | M20: =IF(AND(ROUND($D20,9)>ROUND($C20,9),M$5>ROUND($C20,9),M$5-1<ROUND($D20,9)),"█","") -> █ | ... T20: =IF(AND(ROUND($D20,9)>ROUND($C20,9),T$5>ROUND($C20,9),T$5-1<ROUND($D20,9)),"█","") | U20: =IF(ABS($E$20)<0.000000001,"Actividad Crítica","Holgura de "&ROUND($E$20,4)&" "&IF(ROUND($E$20,4)=1,"semana","semanas")) -> Actividad Crítica
B21: Tardía | C21: ='CPM'!$G$13 -> 7 | D21: ='CPM'!$H$13 -> 10 | F21: =IF(AND(ROUND($D21,9)>ROUND($C21,9),F$5>ROUND($C21,9),F$5-1<ROUND($D21,9)),"█","") | G21: =IF(AND(ROUND($D21,9)>ROUND($C21,9),G$5>ROUND($C21,9),G$5-1<ROUND($D21,9)),"█","") | H21: =IF(AND(ROUND($D21,9)>ROUND($C21,9),H$5>ROUND($C21,9),H$5-1<ROUND($D21,9)),"█","") | I21: =IF(AND(ROUND($D21,9)>ROUND($C21,9),I$5>ROUND($C21,9),I$5-1<ROUND($D21,9)),"█","") | J21: =IF(AND(ROUND($D21,9)>ROUND($C21,9),J$5>ROUND($C21,9),J$5-1<ROUND($D21,9)),"█","") | K21: =IF(AND(ROUND($D21,9)>ROUND($C21,9),K$5>ROUND($C21,9),K$5-1<ROUND($D21,9)),"█","") | L21: =IF(AND(ROUND($D21,9)>ROUND($C21,9),L$5>ROUND($C21,9),L$5-1<ROUND($D21,9)),"█","") | M21: =IF(AND(ROUND($D21,9)>ROUND($C21,9),M$5>ROUND($C21,9),M$5-1<ROUND($D21,9)),"█","") -> █ | ... T21: =IF(AND(ROUND($D21,9)>ROUND($C21,9),T$5>ROUND($C21,9),T$5-1<ROUND($D21,9)),"█","")
A22: I | B22: Temprana | C22: ='CPM'!$E$14 -> 7 | D22: ='CPM'!$F$14 -> 11 | E22: ='CPM'!$I$14 -> 4 | F22: =IF(AND(ROUND($D22,9)>ROUND($C22,9),F$5>ROUND($C22,9),F$5-1<ROUND($D22,9)),"█","") | G22: =IF(AND(ROUND($D22,9)>ROUND($C22,9),G$5>ROUND($C22,9),G$5-1<ROUND($D22,9)),"█","") | H22: =IF(AND(ROUND($D22,9)>ROUND($C22,9),H$5>ROUND($C22,9),H$5-1<ROUND($D22,9)),"█","") | I22: =IF(AND(ROUND($D22,9)>ROUND($C22,9),I$5>ROUND($C22,9),I$5-1<ROUND($D22,9)),"█","") | J22: =IF(AND(ROUND($D22,9)>ROUND($C22,9),J$5>ROUND($C22,9),J$5-1<ROUND($D22,9)),"█","") | K22: =IF(AND(ROUND($D22,9)>ROUND($C22,9),K$5>ROUND($C22,9),K$5-1<ROUND($D22,9)),"█","") | L22: =IF(AND(ROUND($D22,9)>ROUND($C22,9),L$5>ROUND($C22,9),L$5-1<ROUND($D22,9)),"█","") | M22: =IF(AND(ROUND($D22,9)>ROUND($C22,9),M$5>ROUND($C22,9),M$5-1<ROUND($D22,9)),"█","") -> █ | ... T22: =IF(AND(ROUND($D22,9)>ROUND($C22,9),T$5>ROUND($C22,9),T$5-1<ROUND($D22,9)),"█","") | U22: =IF(ABS($E$22)<0.000000001,"Actividad Crítica","Holgura de "&ROUND($E$22,4)&" "&IF(ROUND($E$22,4)=1,"semana","semanas")) -> Holgura de 4 semanas
B23: Tardía | C23: ='CPM'!$G$14 -> 11 | D23: ='CPM'!$H$14 -> 15 | F23: =IF(AND(ROUND($D23,9)>ROUND($C23,9),F$5>ROUND($C23,9),F$5-1<ROUND($D23,9)),"█","") | G23: =IF(AND(ROUND($D23,9)>ROUND($C23,9),G$5>ROUND($C23,9),G$5-1<ROUND($D23,9)),"█","") | H23: =IF(AND(ROUND($D23,9)>ROUND($C23,9),H$5>ROUND($C23,9),H$5-1<ROUND($D23,9)),"█","") | I23: =IF(AND(ROUND($D23,9)>ROUND($C23,9),I$5>ROUND($C23,9),I$5-1<ROUND($D23,9)),"█","") | J23: =IF(AND(ROUND($D23,9)>ROUND($C23,9),J$5>ROUND($C23,9),J$5-1<ROUND($D23,9)),"█","") | K23: =IF(AND(ROUND($D23,9)>ROUND($C23,9),K$5>ROUND($C23,9),K$5-1<ROUND($D23,9)),"█","") | L23: =IF(AND(ROUND($D23,9)>ROUND($C23,9),L$5>ROUND($C23,9),L$5-1<ROUND($D23,9)),"█","") | M23: =IF(AND(ROUND($D23,9)>ROUND($C23,9),M$5>ROUND($C23,9),M$5-1<ROUND($D23,9)),"█","") | ... T23: =IF(AND(ROUND($D23,9)>ROUND($C23,9),T$5>ROUND($C23,9),T$5-1<ROUND($D23,9)),"█","") -> █
A24: J | B24: Temprana | C24: ='CPM'!$E$15 -> 10 | D24: ='CPM'!$F$15 -> 15 | E24: ='CPM'!$I$15 -> 0 | F24: =IF(AND(ROUND($D24,9)>ROUND($C24,9),F$5>ROUND($C24,9),F$5-1<ROUND($D24,9)),"█","") | G24: =IF(AND(ROUND($D24,9)>ROUND($C24,9),G$5>ROUND($C24,9),G$5-1<ROUND($D24,9)),"█","") | H24: =IF(AND(ROUND($D24,9)>ROUND($C24,9),H$5>ROUND($C24,9),H$5-1<ROUND($D24,9)),"█","") | I24: =IF(AND(ROUND($D24,9)>ROUND($C24,9),I$5>ROUND($C24,9),I$5-1<ROUND($D24,9)),"█","") | J24: =IF(AND(ROUND($D24,9)>ROUND($C24,9),J$5>ROUND($C24,9),J$5-1<ROUND($D24,9)),"█","") | K24: =IF(AND(ROUND($D24,9)>ROUND($C24,9),K$5>ROUND($C24,9),K$5-1<ROUND($D24,9)),"█","") | L24: =IF(AND(ROUND($D24,9)>ROUND($C24,9),L$5>ROUND($C24,9),L$5-1<ROUND($D24,9)),"█","") | M24: =IF(AND(ROUND($D24,9)>ROUND($C24,9),M$5>ROUND($C24,9),M$5-1<ROUND($D24,9)),"█","") | ... T24: =IF(AND(ROUND($D24,9)>ROUND($C24,9),T$5>ROUND($C24,9),T$5-1<ROUND($D24,9)),"█","") -> █ | U24: =IF(ABS($E$24)<0.000000001,"Actividad Crítica","Holgura de "&ROUND($E$24,4)&" "&IF(ROUND($E$24,4)=1,"semana","semanas")) -> Actividad Crítica
B25: Tardía | C25: ='CPM'!$G$15 -> 10 | D25: ='CPM'!$H$15 -> 15 | F25: =IF(AND(ROUND($D25,9)>ROUND($C25,9),F$5>ROUND($C25,9),F$5-1<ROUND($D25,9)),"█","") | G25: =IF(AND(ROUND($D25,9)>ROUND($C25,9),G$5>ROUND($C25,9),G$5-1<ROUND($D25,9)),"█","") | H25: =IF(AND(ROUND($D25,9)>ROUND($C25,9),H$5>ROUND($C25,9),H$5-1<ROUND($D25,9)),"█","") | I25: =IF(AND(ROUND($D25,9)>ROUND($C25,9),I$5>ROUND($C25,9),I$5-1<ROUND($D25,9)),"█","") | J25: =IF(AND(ROUND($D25,9)>ROUND($C25,9),J$5>ROUND($C25,9),J$5-1<ROUND($D25,9)),"█","") | K25: =IF(AND(ROUND($D25,9)>ROUND($C25,9),K$5>ROUND($C25,9),K$5-1<ROUND($D25,9)),"█","") | L25: =IF(AND(ROUND($D25,9)>ROUND($C25,9),L$5>ROUND($C25,9),L$5-1<ROUND($D25,9)),"█","") | M25: =IF(AND(ROUND($D25,9)>ROUND($C25,9),M$5>ROUND($C25,9),M$5-1<ROUND($D25,9)),"█","") | ... T25: =IF(AND(ROUND($D25,9)>ROUND($C25,9),T$5>ROUND($C25,9),T$5-1<ROUND($D25,9)),"█","") -> █

Sheet Probabilidad
A1: PERT probabilístico — probabilidad de terminación
A3: Parámetros
A4: Tiempo esperado mínimo del proyecto (t_e) | C4: ='CPM'!$D$2 -> 15
A5: σ² (Σ σ² A.C.) | C5: ='PERT'!$F$18 -> 4.1111111
A6: σ = √σ² | C6: =SQRT(C5) -> 2.0275875
A7: Z = (T_p − t_e) / σ
A8: Tabla: Z redondeado a 2 decimales y P(Z) leído a 4 decimales (convención del material de referencia). Exacto: función NORMSDIST.
A10: Pregunta | B10: Tipo | C10: T_p | D10: Z exacto | E10: P(Z ≤ z) exacta | F10: Z tabla | G10: P(Z ≤ z) tabla | H10: Probabilidad (exacta) | I10: Probabilidad (tabla) | J10: Interpretación
A11: d | B11: T ≤ 13 | C11: 13 | D11: =(C11-$C$4)/$C$6 -> -0.98639392 | E11: =NORMSDIST(D11) -> 0.16196992 | F11: =ROUND(D11,2) -> -0.99 | G11: =ROUND(NORMSDIST(F11),4) -> 0.1611 | H11: =E11 -> 0.16196992 | I11: =G11 -> 0.1611 | J11: P(T ≤ 13) = 0.1620
A12: e | B12: T ≥ 16 | C12: 16 | D12: =(C12-$C$4)/$C$6 -> 0.49319696 | E12: =NORMSDIST(D12) -> 0.68906329 | F12: =ROUND(D12,2) -> 0.49 | G12: =ROUND(NORMSDIST(F12),4) -> 0.6879 | H12: =1-E12 -> 0.31093671 | I12: =ROUND(1-G12,4) -> 0.3121 | J12: P(T ≥ 16) = 0.3109
A13: f | B13: 16 ≤ T ≤ 20 | C13: 20 | D13: =(C13-$C$4)/$C$6 -> 2.4659848 | E13: =NORMSDIST(D13) -> 0.99316814 | F13: =ROUND(D13,2) -> 2.47 | G13: =ROUND(NORMSDIST(F13),4) -> 0.9932 | H13: =E13-E14 -> 0.30410486 | I13: =ROUND(G13-G14,4) -> 0.3053 | J13: P(16 ≤ T ≤ 20) = 0.3041
A14: f | B14: 16 ≤ T ≤ 20 | C14: 16 | D14: =(C14-$C$4)/$C$6 -> 0.49319696 | E14: =NORMSDIST(D14) -> 0.68906329 | F14: =ROUND(D14,2) -> 0.49 | G14: =ROUND(NORMSDIST(F14),4) -> 0.6879
A16: Duración para una probabilidad objetivo: T_p = t_e + Z·σ
A17: Pregunta | B17: Probabilidad objetivo | C17: Z exacto | D17: T_p exacto | E17: Z tabla | F17: P(Z ≤ z) tabla | G17: T_p con Z de tabla | H17: Duración a especificar (entero superior) | I17: Interpretación
A18: g | B18: 0.98 | C18: =NORMSINV(B18) -> 2.0537489 | D18: =$C$4+C18*$C$6 -> 19.164156 | E18: 2.06 | F18: =ROUND(NORMSDIST(E18),4) -> 0.9803 | G18: =$C$4+E18*$C$6 -> 19.17683 | H18: =ROUNDUP(ROUND(D18,9),0) -> 20 | I18: P = 0.98 → 20 semanas
A19: Z de tabla = menor Z con 2 decimales cuya P(Z) tabulada alcanza la probabilidad objetivo.

Sheet Resultados
A1: Resultados finales
A2: Taller 1 — Administración de proyectos
A4: Parte | B4: Pregunta | C4: Respuesta | D4: Valor clave (vinculado)
A5: a | B5: Elabore el diagrama Gantt | C5: Diagrama Gantt en la hoja 'Gantt': 10 actividades en 15 semanas; barras de tiempos más tempranos y más tardíos; observaciones con actividades críticas y holguras.
A6: b | B6: Para cada actividad los tiempos de inicio más temprano, inicio más tardío, terminación más temprana, terminación más tardía y la holgura. | C6: (hoja 'CPM') A: IC 0, TC 2, IL 0, TL 2, holgura 0; B: IC 2, TC 5, IL 3, TL 6, holgura 1; C: IC 2, TC 6, IL 2, TL 6, holgura 0; D: IC 5, TC 10, IL 8, TL 13, holgura 3; E: IC 10, TC 12, IL 13, TL 15, holgura 3; F: IC 6, TC 7, IL 6, TL 7, holgura 0; G: IC 6, TC 7, IL 10, TL 11, holgura 4; H: IC 7, TC 10, IL 7, TL 10, holgura 0; I: IC 7, TC 11, IL 11, TL 15, holgura 4; J: IC 10, TC 15, IL 10, TL 15, holgura 0.
A7: c | B7: El tiempo mínimo esperado del proyecto, su varianza y las actividades de la ruta crítica. | C7: Ruta crítica: A – C – F – H – J. Tiempo esperado mínimo del proyecto (t_e): 15 semanas. Varianza del proyecto: σ² = 1/9 + 16/9 + 0 + 4/9 + 16/9 = 37/9 ≈ 4.1111; desviación estándar σ = √(37/9) = 2.0276. | D7: ='CPM'!$D$3 -> A – C – F – H – J
A8: d | B8: La probabilidad de terminar el proyecto en 13 semanas o menos. | C8: P(T ≤ 13) = 0.1620 (Z = -0.9864; con tabla: 0.1611). | D8: ='Probabilidad'!$H$11 -> 0.16196992
A9: e | B9: La probabilidad de terminar el proyecto en 16 semanas o más. | C9: P(T ≥ 16) = 0.3109 (Z = 0.4932; con tabla: 0.3121). | D9: ='Probabilidad'!$H$12 -> 0.31093671
A10: f | B10: La probabilidad de desarrollar el proyecto entre 16 y 20 semanas. | C10: P(16 ≤ T ≤ 20) = 0.3041 (Z = 2.466, Z = 0.4932; con tabla: 0.3053). | D10: ='Probabilidad'!$H$13 -> 0.30410486
A11: g | B11: Si se desea firmar un contrato que especifique el tiempo de terminación del proyecto de modo que haya una probabilidad del 98 % de cumplir la fecha deseada, ¿Qué duración debería especificarse en el contrato? | C11: Para 98 %: Z = 2.0537 → T = 19.1642; con tabla Z = 2.06 → T = 19.1768; duración a especificar: 20 semanas. | D11: ='Probabilidad'!$H$18 -> 20
A13: Procedencia de los datos
A14: Procedencia | B14: Actividades | C14: Campo
A15: Extraído del documento | B15: 10
A16: Inferido | B16: 0 | C16: A.predecessors, B.predecessors, C.predecessors, D.predecessors, E.predecessors, F.predecessors, G.predecessors, H.predecessors, I.predecessors, J.predecessors
A18: Supuestos e inferencias
A19: Campo | B19: Valor | C19: Justificación | D19: Procedencia
A20: requested_outputs | B20: GANTT | C20: Question 'a' asks for it. | D20: Inferido
A21: requested_outputs | B21: EARLY_LATE_TIMES | C21: Question 'b' asks for it. | D21: Inferido
A22: requested_outputs | B22: SLACK | C22: Question 'b' asks for it. | D22: Inferido
A23: requested_outputs | B23: CRITICAL_PATH | C23: Question 'c' asks for it. | D23: Inferido
A24: requested_outputs | B24: EXPECTED_DURATION | C24: Question 'c' asks for it. | D24: Inferido
A25: requested_outputs | B25: VARIANCE | C25: Question 'c' asks for it. | D25: Inferido
A26: requested_outputs | B26: PROBABILITY_QUERY | C26: Question 'd' asks for it. | D26: Inferido
A27: requested_outputs | B27: PERCENTILE_DURATION | C27: Question 'g' asks for it. | D27: Inferido
A28: calculation_method | B28: PERT | C28: Every activity has optimistic, most likely and pessimistic durations. | D28: Inferido
A30: Validación independiente de los cálculos
A31: Verificación | B31: ¿Correcta? | C31: Detalle
A32: network arcs match the activity predecessor lists | B32: Sí | C32: ok
A33: PERT t_e = a/6 + 2m/3 + b/6 and σ² = (b−a)²/36 | B33: Sí | C33: ok
A34: schedule: durations match their source | B34: Sí | C34: ok
A35: schedule: EF−ES = LF−LS = duration and LS−ES = LF−EF | B35: Sí | C35: ok
A36: schedule: every precedence respected | B36: Sí | C36: ok
A37: schedule: project duration = longest path (independent relaxation) | B37: Sí | C37: ok
A38: schedule: each critical path sums to the project duration | B38: Sí | C38: ok
A39: project variance re-summed from the raw estimates | B39: Sí | C39: ok
A40: probabilities re-derived by numerical integration of the normal pdf | B40: Sí | C40: ok
A41: percentile durations re-derived (Φ(Z) round-trip, table rule) | B41: Sí | C41: ok
A42: Gantt bars match ES→EF / LS→LF and critical flags | B42: Sí | C42: ok
